Workbook

Sheet Prévisions Dépenses-Décaiss
C19: Prévisions Dépenses
A25: Elements Periodes | C25: Janvier 1-7 | D25: Janvier 8-15 | E25: Janvier 16-23 | F25: Janvier 24-31 | G25: Fevrier 1-7 | H25: Fevrier 8-15 | I25: Fevrier 16-23 | J25: Fevrier 24-28 | K25: Mars 1-7 | L25: Mars 8-15 | M25: Mars 16-23 | N25: Mars 24-31
A26: Fixes | B26: Salaire Net
B27: IRG
B28: Secu 35%
B29: Abon.tel
B30: Loyer
A31: Total Fixes | C31: =SUM(C26:C30) -> 0 | D31: =SUM(D26:D30) -> 0 | E31: =SUM(E26:E30) -> 0 | F31: =SUM(F26:F30) -> 0 | G31: =SUM(G26:G30) -> 0 | H31: =SUM(H26:H30) -> 0 | I31: =SUM(I26:I30) -> 0 | J31: =SUM(J26:J30) -> 0 | ... N31: =SUM(N26:N30) -> 0
A32: Variables | B32: G50 TAP
B33: G50 TVA
B34: G50 ACOMPTE IBS
B35: Achats materiels
B36: Autres
A37: Total Variables | C37: =SUM(C32:C36) -> 0 | D37: =SUM(D32:D36) -> 0 | E37: =SUM(E32:E36) -> 0 | F37: =SUM(F32:F36) -> 0 | G37: =SUM(G32:G36) -> 0 | H37: =SUM(H32:H36) -> 0 | I37: =SUM(I32:I36) -> 0 | J37: =SUM(J32:J36) -> 0 | ... N37: =SUM(N32:N36) -> 0
A38: Total depenses periode | C38: =C31+C37 -> 0 | D38: =D31+D37 -> 0 | E38: =E31+E37 -> 0 | F38: =F31+F37 -> 0 | G38: =G31+G37 -> 0 | H38: =H31+H37 -> 0 | I38: =I31+I37 -> 0 | J38: =J31+J37 -> 0 | ... N38: =N31+N37 -> 0
A39: Total depenses mois | C39: =C38+D38+E38+F38 -> 0 | G39: =G38+H38+I38+J38 -> 0 | K39: =K38+L38+M38+N38 -> 0
A43: Elements Periodes | C43: Avril 1-7 | D43: Avril 8-15 | E43: Avril 16-23 | F43: Avril 24-30 | G43: Mai 1-7 | H43: Mai 8-15 | I43: Mai 16-23 | J43: Mai 24-31 | K43: Juin 1-7 | L43: Juin 8-15 | M43: Juin 16-23 | N43: Juin 24-30
A44: Fixes | B44: Salaire Net
B45: IRG
B46: Secu 35%
B47: Abon.tel
B48: Loyer
A49: Total Fixes | C49: =SUM(C44:C48) -> 0 | D49: =SUM(D44:D48) -> 0 | E49: =SUM(E44:E48) -> 0 | F49: =SUM(F44:F48) -> 0 | G49: =SUM(G44:G48) -> 0 | H49: =SUM(H44:H48) -> 0 | I49: =SUM(I44:I48) -> 0 | J49: =SUM(J44:J48) -> 0 | ... N49: =SUM(N44:N48) -> 0
A50: Variables | B50: G50 TAP
B51: G50 TVA
B52: G50 ACOMPTE IBS
B53: Achats materiels
B54: Autres
A55: Total Variables | C55: =SUM(C50:C54) -> 0 | D55: =SUM(D50:D54) -> 0 | E55: =SUM(E50:E54) -> 0 | F55: =SUM(F50:F54) -> 0 | G55: =SUM(G50:G54) -> 0 | H55: =SUM(H50:H54) -> 0 | I55: =SUM(I50:I54) -> 0 | J55: =SUM(J50:J54) -> 0 | ... N55: =SUM(N50:N54) -> 0
A56: Total depenses periode | C56: =C49+C55 -> 0 | D56: =D49+D55 -> 0 | E56: =E49+E55 -> 0 | F56: =F49+F55 -> 0 | G56: =G49+G55 -> 0 | H56: =H49+H55 -> 0 | I56: =I49+I55 -> 0 | J56: =J49+J55 -> 0 | ... N56: =N49+N55 -> 0
A57: Total depenses mois | C57: =C56+D56+E56+F56 -> 0 | G57: =G56+H56+I56+J56 -> 0 | K57: =K56+L56+M56+N56 -> 0
A61: Elements Periodes | C61: Juillet 1-7 | D61: Juillet 8-15 | E61: Juillet 16-23 | F61: Juillet 24-31 | G61: Aout 1-7 | H61: Aout 8-15 | I61: Aout 16-23 | J61: Aout 24-31 | K61: Septembre 1-7 | L61: Septembre 8-15 | M61: Septembre 16-23 | N61: Septembre 24-31
A62: Fixes | B62: Salaire Net
B63: IRG
B64: Secu 35%
B65: Abon.tel
B66: Loyer
A67: Total Fixes | C67: =SUM(C62:C66) -> 0 | D67: =SUM(D62:D66) -> 0 | E67: =SUM(E62:E66) -> 0 | F67: =SUM(F62:F66) -> 0 | G67: =SUM(G62:G66) -> 0 | H67: =SUM(H62:H66) -> 0 | I67: =SUM(I62:I66) -> 0 | J67: =SUM(J62:J66) -> 0 | ... N67: =SUM(N62:N66) -> 0
A68: Variables | B68: G50 TAP
B69: G50 TVA
...

Sheet Prévisions Entrées-Encaiss
C17: Prévisions Encaissements
A24: Elements Periodes | C24: Janvier 1-7 | D24: Janvier 8-15 | E24: Janvier 16-23 | F24: Janvier 24-31 | G24: Fevrier 1-7 | H24: Fevrier 8-15 | I24: Fevrier 16-23 | J24: Fevrier 24-28 | K24: Mars 1-7 | L24: Mars 8-15 | M24: Mars 16-23 | N24: Mars 24-31
A25: Clients | B25: Henkel
B26: KNAUF
B27: MyTeamConnect
B28: Lafarge
B29: DIGITAL NATIVES
B30: Beyond
B31: Kimmco
B32: Insersite
B33: In Solutions
B34: Impact design
A35: Autres ( tva déductibles)
A36: Total encaissements periode HT | C36: =SUM(Tableau13[Janvier 1-7]) -> 0 | D36: =SUM(Tableau13[Janvier 8-15]) -> 0 | E36: =SUM(Tableau13[Janvier 16-23]) -> 0 | F36: =SUM(Tableau13[Janvier 24-31]) -> 0 | G36: =SUM(Tableau13[Fevrier 1-7]) -> 0 | H36: =SUM(Tableau13[Fevrier 8-15]) -> 0 | I36: =SUM(Tableau13[Fevrier 16-23]) -> 0 | J36: =SUM(Tableau13[Fevrier 24-28]) -> 0 | K36: =SUM(Tableau13[Mars 1-7]) -> 0 | L36: =SUM(Tableau13[Mars 8-15]) -> 0 | M36: =SUM(Tableau13[Mars 16-23]) -> 0 | N36: =SUM(Tableau13[Mars 24-31]) -> 0
A37: Total encaissements mois | C37: =SUM(C36:F36) -> 0 | G37: =SUM(G36:J36) -> 0 | K37: =SUM(K36:N36) -> 0
A41: Elements Periodes | C41: Avril 1-7 | D41: Avril 8-15 | E41: Avril 16-23 | F41: Avril 24-30 | G41: Mai 1-7 | H41: Mai 8-15 | I41: Mai 16-23 | J41: Mai 24-31 | K41: Juin 1-7 | L41: Juin 8-15 | M41: Juin 16-23 | N41: Juin 24-30
A42: Clients | B42: Henkel
B43: KNAUF
B44: MyTeamConnect
B45: Lafarge
B46: DIGITAL NATIVES
B47: Beyond
B48: Kimmco
B49: Insersite
B50: In Solutions
B51: Impact design
A52: Autres ( tva déductibles)
A53: Total encaissements periode | C53: =SUM(C42:C52) -> 0 | D53: =SUM(D42:D52) -> 0 | E53: =SUM(E42:E52) -> 0 | F53: =SUM(F42:F52) -> 0 | G53: =SUM(G42:G52) -> 0 | H53: =SUM(H42:H52) -> 0 | I53: =SUM(I42:I52) -> 0 | J53: =SUM(J42:J52) -> 0 | ... N53: =SUM(N42:N52) -> 0
A54: Total encaissements mois | C54: =SUM(C53:F53) -> 0 | G54: =SUM(G53:J53) -> 0 | K54: =SUM(K53:N53) -> 0
A58: Elements Periodes | C58: Juillet 1-7 | D58: Juillet 8-15 | E58: Juillet 16-23 | F58: Juillet 24-31 | G58: Aout 1-7 | H58: Aout 8-15 | I58: Aout 16-23 | J58: Aout 24-31 | K58: Septembre 1-7 | L58: Septembre 8-15 | M58: Septembre 16-23 | N58: Septembre 24-30
A59: Clients | B59: Henkel
B60: KNAUF
B61: MyTeamConnect
B62: Lafarge
B63: DIGITAL NATIVES
B64: Beyond
B65: Kimmco
B66: Insersite
B67: In Solutions
B68: Impact design
...

Sheet Flux de trésorerie
D14: FLUX DE TRESORERIE ET GESTION BUDGETAIRE
A22: Elements Periodes | C22: Janvier 1-7 | D22: Janvier 8-15 | E22: Janvier 16-23 | F22: Janvier 24-31 | G22: Fevrier 1-7 | H22: Fevrier 8-15 | I22: Fevrier 16-23 | J22: Fevrier 24-28 | K22: Mars 1-7 | L22: Mars 8-15 | M22: Mars 16-23 | N22: Mars 24-31
A23: Encaissements
A24: Clients | B24: Henkel | C24: ='Prévisions Entrées-Encaiss'!C25 -> 0 | D24: ='Prévisions Entrées-Encaiss'!D25 -> 0 | E24: ='Prévisions Entrées-Encaiss'!E25 -> 0 | F24: ='Prévisions Entrées-Encaiss'!F25 -> 0 | G24: ='Prévisions Entrées-Encaiss'!G25 -> 0 | H24: ='Prévisions Entrées-Encaiss'!H25 -> 0 | I24: ='Prévisions Entrées-Encaiss'!I25 -> 0 | J24: ='Prévisions Entrées-Encaiss'!J25 -> 0 | ... N24: ='Prévisions Entrées-Encaiss'!N25 -> 0
B25: KNAUF | C25: ='[1]Prévisions Entrées-Encaiss'!C26 -> 0 | D25: ='[1]Prévisions Entrées-Encaiss'!D26 -> 0 | E25: ='[1]Prévisions Entrées-Encaiss'!E26 -> 0 | F25: ='[1]Prévisions Entrées-Encaiss'!F26 -> 0 | G25: ='[1]Prévisions Entrées-Encaiss'!G26 -> 0 | H25: ='[1]Prévisions Entrées-Encaiss'!H26 -> 0 | I25: ='[1]Prévisions Entrées-Encaiss'!I26 -> 0 | J25: ='[1]Prévisions Entrées-Encaiss'!J26 -> 0 | ... N25: ='[1]Prévisions Entrées-Encaiss'!N26 -> 0
B26: MyTeamConnect | C26: ='[1]Prévisions Entrées-Encaiss'!C27 -> 0 | D26: ='[1]Prévisions Entrées-Encaiss'!D27 -> 0 | E26: ='[1]Prévisions Entrées-Encaiss'!E27 -> 0 | F26: ='[1]Prévisions Entrées-Encaiss'!F27 -> 0 | G26: ='[1]Prévisions Entrées-Encaiss'!G27 -> 0 | H26: ='[1]Prévisions Entrées-Encaiss'!H27 -> 0 | I26: ='[1]Prévisions Entrées-Encaiss'!I27 -> 0 | J26: ='[1]Prévisions Entrées-Encaiss'!J27 -> 0 | ... N26: ='[1]Prévisions Entrées-Encaiss'!N27 -> 0
B27: Lafarge | C27: ='[1]Prévisions Entrées-Encaiss'!C28 -> 0 | D27: ='[1]Prévisions Entrées-Encaiss'!D28 -> 0 | E27: ='[1]Prévisions Entrées-Encaiss'!E28 -> 0 | F27: ='[1]Prévisions Entrées-Encaiss'!F28 -> 0 | G27: ='[1]Prévisions Entrées-Encaiss'!G28 -> 0 | H27: ='[1]Prévisions Entrées-Encaiss'!H28 -> 0 | I27: ='[1]Prévisions Entrées-Encaiss'!I28 -> 0 | J27: ='[1]Prévisions Entrées-Encaiss'!J28 -> 0 | ... N27: ='[1]Prévisions Entrées-Encaiss'!N28 -> 0
B28: DIGITAL NATIVES | C28: ='[1]Prévisions Entrées-Encaiss'!C29 -> 0 | D28: ='[1]Prévisions Entrées-Encaiss'!D29 -> 0 | E28: ='[1]Prévisions Entrées-Encaiss'!E29 -> 0 | F28: ='[1]Prévisions Entrées-Encaiss'!F29 -> 0 | G28: ='[1]Prévisions Entrées-Encaiss'!G29 -> 0 | H28: ='[1]Prévisions Entrées-Encaiss'!H29 -> 0 | I28: ='[1]Prévisions Entrées-Encaiss'!I29 -> 0 | J28: ='[1]Prévisions Entrées-Encaiss'!J29 -> 0 | ... N28: ='[1]Prévisions Entrées-Encaiss'!N29 -> 0
B29: Beyond | C29: ='[1]Prévisions Entrées-Encaiss'!C30 -> 0 | D29: ='[1]Prévisions Entrées-Encaiss'!D30 -> 0 | E29: ='[1]Prévisions Entrées-Encaiss'!E30 -> 0 | F29: ='[1]Prévisions Entrées-Encaiss'!F30 -> 0 | G29: ='[1]Prévisions Entrées-Encaiss'!G30 -> 0 | H29: ='[1]Prévisions Entrées-Encaiss'!H30 -> 0 | I29: ='[1]Prévisions Entrées-Encaiss'!I30 -> 0 | J29: ='[1]Prévisions Entrées-Encaiss'!J30 -> 0 | ... N29: ='[1]Prévisions Entrées-Encaiss'!N30 -> 0
B30: Kimmco | C30: ='[1]Prévisions Entrées-Encaiss'!C31 -> 0 | D30: ='[1]Prévisions Entrées-Encaiss'!D31 -> 0 | E30: ='[1]Prévisions Entrées-Encaiss'!E31 -> 0 | F30: ='[1]Prévisions Entrées-Encaiss'!F31 -> 0 | G30: ='[1]Prévisions Entrées-Encaiss'!G31 -> 0 | H30: ='[1]Prévisions Entrées-Encaiss'!H31 -> 0 | I30: ='[1]Prévisions Entrées-Encaiss'!I31 -> 0 | J30: ='[1]Prévisions Entrées-Encaiss'!J31 -> 0 | ... N30: ='[1]Prévisions Entrées-Encaiss'!N31 -> 0
B31: Insersite | C31: ='[1]Prévisions Entrées-Encaiss'!C32 -> 0 | D31: ='[1]Prévisions Entrées-Encaiss'!D32 -> 0 | E31: ='[1]Prévisions Entrées-Encaiss'!E32 -> 0 | F31: ='[1]Prévisions Entrées-Encaiss'!F32 -> 0 | G31: ='[1]Prévisions Entrées-Encaiss'!G32 -> 0 | H31: ='[1]Prévisions Entrées-Encaiss'!H32 -> 0 | I31: ='[1]Prévisions Entrées-Encaiss'!I32 -> 0 | J31: ='[1]Prévisions Entrées-Encaiss'!J32 -> 0 | ... N31: ='[1]Prévisions Entrées-Encaiss'!N32 -> 0
B32: In Solutions | C32: ='[1]Prévisions Entrées-Encaiss'!C33 -> 0 | D32: ='[1]Prévisions Entrées-Encaiss'!D33 -> 0 | E32: ='[1]Prévisions Entrées-Encaiss'!E33 -> 0 | F32: ='[1]Prévisions Entrées-Encaiss'!F33 -> 0 | G32: ='[1]Prévisions Entrées-Encaiss'!G33 -> 0 | H32: ='[1]Prévisions Entrées-Encaiss'!H33 -> 0 | I32: ='[1]Prévisions Entrées-Encaiss'!I33 -> 0 | J32: ='[1]Prévisions Entrées-Encaiss'!J33 -> 0 | ... N32: ='[1]Prévisions Entrées-Encaiss'!N33 -> 0
B33: Impact design | C33: ='[1]Prévisions Entrées-Encaiss'!C34 -> 0 | D33: ='[1]Prévisions Entrées-Encaiss'!D34 -> 0 | E33: ='[1]Prévisions Entrées-Encaiss'!E34 -> 0 | F33: ='[1]Prévisions Entrées-Encaiss'!F34 -> 0 | G33: ='[1]Prévisions Entrées-Encaiss'!G34 -> 0 | H33: ='[1]Prévisions Entrées-Encaiss'!H34 -> 0 | I33: ='[1]Prévisions Entrées-Encaiss'!I34 -> 0 | J33: ='[1]Prévisions Entrées-Encaiss'!J34 -> 0 | ... N33: ='[1]Prévisions Entrées-Encaiss'!N34 -> 0
A34: Autres ( tva déductibles,,,) | C34: ='[1]Prévisions Entrées-Encaiss'!C35 -> 0 | D34: ='[1]Prévisions Entrées-Encaiss'!D35 -> 0 | E34: ='[1]Prévisions Entrées-Encaiss'!E35 -> 0 | F34: ='[1]Prévisions Entrées-Encaiss'!F35 -> 0 | G34: ='[1]Prévisions Entrées-Encaiss'!G35 -> 0 | H34: ='[1]Prévisions Entrées-Encaiss'!H35 -> 0 | I34: ='[1]Prévisions Entrées-Encaiss'!I35 -> 0 | J34: ='[1]Prévisions Entrées-Encaiss'!J35 -> 0 | ... N34: ='[1]Prévisions Entrées-Encaiss'!N35 -> 0
A35: TOTAL Encaissements | C35: =SUM(C24:C34) -> 0 | D35: =SUM(D24:D34) -> 0 | E35: =SUM(E24:E34) -> 0 | F35: =SUM(F24:F34) -> 0 | G35: =SUM(G24:G34) -> 0 | H35: =SUM(H24:H34) -> 0 | I35: =SUM(I24:I34) -> 0 | J35: =SUM(J24:J34) -> 0 | ... N35: =SUM(N24:N34) -> 0
A36: Décaissements
A37: Salaire Net | C37: ='Prévisions Dépenses-Décaiss'!C26 -> 0 | D37: ='Prévisions Dépenses-Décaiss'!D26 -> 0 | E37: ='Prévisions Dépenses-Décaiss'!E26 -> 0 | F37: ='Prévisions Dépenses-Décaiss'!F26 -> 0 | G37: ='Prévisions Dépenses-Décaiss'!G26 -> 0 | H37: ='Prévisions Dépenses-Décaiss'!H26 -> 0 | I37: ='Prévisions Dépenses-Décaiss'!I26 -> 0 | J37: ='Prévisions Dépenses-Décaiss'!J26 -> 0 | ... N37: ='Prévisions Dépenses-Décaiss'!N26 -> 0
A38: IRG G50 | C38: ='[1]Prévisions Dépenses-Décaiss'!C27 -> 0 | D38: ='[1]Prévisions Dépenses-Décaiss'!D27 -> 0 | E38: ='[1]Prévisions Dépenses-Décaiss'!E27 -> 0 | F38: ='[1]Prévisions Dépenses-Décaiss'!F27 -> 0 | G38: ='[1]Prévisions Dépenses-Décaiss'!G27 -> 0 | H38: ='[1]Prévisions Dépenses-Décaiss'!H27 -> 0 | I38: ='[1]Prévisions Dépenses-Décaiss'!I27 -> 0 | J38: ='[1]Prévisions Dépenses-Décaiss'!J27 -> 0 | ... N38: ='[1]Prévisions Dépenses-Décaiss'!N27 -> 0
A39: Secu 35% | C39: ='[1]Prévisions Dépenses-Décaiss'!C28 -> 0 | D39: ='[1]Prévisions Dépenses-Décaiss'!D28 -> 0 | E39: ='[1]Prévisions Dépenses-Décaiss'!E28 -> 0 | F39: ='[1]Prévisions Dépenses-Décaiss'!F28 -> 0 | G39: ='[1]Prévisions Dépenses-Décaiss'!G28 -> 0 | H39: ='[1]Prévisions Dépenses-Décaiss'!H28 -> 0 | I39: ='[1]Prévisions Dépenses-Décaiss'!I28 -> 0 | J39: ='[1]Prévisions Dépenses-Décaiss'!J28 -> 0 | ... N39: ='[1]Prévisions Dépenses-Décaiss'!N28 -> 0
A40: Abon.tel | C40: ='[1]Prévisions Dépenses-Décaiss'!C29 -> 0 | D40: ='[1]Prévisions Dépenses-Décaiss'!D29 -> 0 | E40: ='[1]Prévisions Dépenses-Décaiss'!E29 -> 0 | F40: ='[1]Prévisions Dépenses-Décaiss'!F29 -> 0 | G40: ='[1]Prévisions Dépenses-Décaiss'!G29 -> 0 | H40: ='[1]Prévisions Dépenses-Décaiss'!H29 -> 0 | I40: ='[1]Prévisions Dépenses-Décaiss'!I29 -> 0 | J40: ='[1]Prévisions Dépenses-Décaiss'!J29 -> 0 | ... N40: ='[1]Prévisions Dépenses-Décaiss'!N29 -> 0
A41: Loyer | C41: ='[1]Prévisions Dépenses-Décaiss'!C30 -> 0 | D41: ='[1]Prévisions Dépenses-Décaiss'!D30 -> 0 | E41: ='[1]Prévisions Dépenses-Décaiss'!E30 -> 0 | F41: ='[1]Prévisions Dépenses-Décaiss'!F30 -> 0 | G41: ='[1]Prévisions Dépenses-Décaiss'!G30 -> 0 | H41: ='[1]Prévisions Dépenses-Décaiss'!H30 -> 0 | I41: ='[1]Prévisions Dépenses-Décaiss'!I30 -> 0 | J41: ='[1]Prévisions Dépenses-Décaiss'!J30 -> 0 | ... N41: ='[1]Prévisions Dépenses-Décaiss'!N30 -> 0
A42: G50 Hors IRG | B42: TAP | C42: ='[1]Prévisions Dépenses-Décaiss'!C32 -> 0 | D42: ='[1]Prévisions Dépenses-Décaiss'!D32 -> 0 | E42: ='[1]Prévisions Dépenses-Décaiss'!E32 -> 0 | F42: ='[1]Prévisions Dépenses-Décaiss'!F32 -> 0 | G42: ='[1]Prévisions Dépenses-Décaiss'!G32 -> 0 | H42: ='[1]Prévisions Dépenses-Décaiss'!H32 -> 0 | I42: ='[1]Prévisions Dépenses-Décaiss'!I32 -> 0 | J42: ='[1]Prévisions Dépenses-Décaiss'!J32 -> 0 | ... N42: ='[1]Prévisions Dépenses-Décaiss'!N32 -> 0
B43: TVA | C43: ='[1]Prévisions Dépenses-Décaiss'!C33 -> 0 | D43: ='[1]Prévisions Dépenses-Décaiss'!D33 -> 0 | E43: ='[1]Prévisions Dépenses-Décaiss'!E33 -> 0 | F43: ='[1]Prévisions Dépenses-Décaiss'!F33 -> 0 | G43: ='[1]Prévisions Dépenses-Décaiss'!G33 -> 0 | H43: ='[1]Prévisions Dépenses-Décaiss'!H33 -> 0 | I43: ='[1]Prévisions Dépenses-Décaiss'!I33 -> 0 | J43: ='[1]Prévisions Dépenses-Décaiss'!J33 -> 0 | ... N43: ='[1]Prévisions Dépenses-Décaiss'!N33 -> 0
B44: Acompte IBS | C44: ='[1]Prévisions Dépenses-Décaiss'!C34 -> 0 | D44: ='[1]Prévisions Dépenses-Décaiss'!D34 -> 0 | E44: ='[1]Prévisions Dépenses-Décaiss'!E34 -> 0 | F44: ='[1]Prévisions Dépenses-Décaiss'!F34 -> 0 | G44: ='[1]Prévisions Dépenses-Décaiss'!G34 -> 0 | H44: ='[1]Prévisions Dépenses-Décaiss'!H34 -> 0 | I44: ='[1]Prévisions Dépenses-Décaiss'!I34 -> 0 | J44: ='[1]Prévisions Dépenses-Décaiss'!J34 -> 0 | ... N44: ='[1]Prévisions Dépenses-Décaiss'!N34 -> 0
A45: Achats materiels | C45: ='[1]Prévisions Dépenses-Décaiss'!C35 -> 0 | D45: ='[1]Prévisions Dépenses-Décaiss'!D35 -> 0 | E45: ='[1]Prévisions Dépenses-Décaiss'!E35 -> 0 | F45: ='[1]Prévisions Dépenses-Décaiss'!F35 -> 0 | G45: ='[1]Prévisions Dépenses-Décaiss'!G35 -> 0 | H45: ='[1]Prévisions Dépenses-Décaiss'!H35 -> 0 | I45: ='[1]Prévisions Dépenses-Décaiss'!I35 -> 0 | J45: ='[1]Prévisions Dépenses-Décaiss'!J35 -> 0 | ... N45: ='[1]Prévisions Dépenses-Décaiss'!N35 -> 0
A46: Autres | C46: ='[1]Prévisions Dépenses-Décaiss'!C36 -> 0 | D46: ='[1]Prévisions Dépenses-Décaiss'!D36 -> 0 | E46: ='[1]Prévisions Dépenses-Décaiss'!E36 -> 0 | F46: ='[1]Prévisions Dépenses-Décaiss'!F36 -> 0 | G46: ='[1]Prévisions Dépenses-Décaiss'!G36 -> 0 | H46: ='[1]Prévisions Dépenses-Décaiss'!H36 -> 0 | I46: ='[1]Prévisions Dépenses-Décaiss'!I36 -> 0 | J46: ='[1]Prévisions Dépenses-Décaiss'!J36 -> 0 | ... N46: ='[1]Prévisions Dépenses-Décaiss'!N36 -> 0
A47: TOTAL Décaissements | C47: =SUM(C37:C46) -> 0 | D47: =SUM(D37:D46) -> 0 | E47: =SUM(E37:E46) -> 0 | F47: =SUM(F37:F46) -> 0 | G47: =SUM(G37:G46) -> 0 | H47: =SUM(H37:H46) -> 0 | I47: =SUM(I37:I46) -> 0 | J47: =SUM(J37:J46) -> 0 | ... N47: =SUM(N37:N46) -> 0
A48: Trésorerie initiale | D48: =C52 -> 0 | E48: =D52 -> 0 | F48: =E52 -> 0 | G48: =F52 -> 0 | H48: =G52 -> 0 | I48: =H52 -> 0 | J48: =I52 -> 0 | K48: =J52 -> 0 | ... N48: =M52 -> 0
A49: Encaissements | C49: =C35 -> 0 | D49: =D35 -> 0 | E49: =E35 -> 0 | F49: =F35 -> 0 | G49: =G35 -> 0 | H49: =H35 -> 0 | I49: =I35 -> 0 | J49: =J35 -> 0 | ... N49: =N35 -> 0
A50: Décaissements | C50: =C47 -> 0 | D50: =D47 -> 0 | E50: =E47 -> 0 | F50: =F47 -> 0 | G50: =G47 -> 0 | H50: =H47 -> 0 | I50: =I47 -> 0 | J50: =J47 -> 0 | ... N50: =N47 -> 0
A51: Solde periode | C51: =C49-C50 -> 0 | D51: =D49-D50 -> 0 | E51: =E49-E50 -> 0 | F51: =F49-F50 -> 0 | G51: =G49-G50 -> 0 | H51: =H49-H50 -> 0 | I51: =I49-I50 -> 0 | J51: =J49-J50 -> 0 | ... N51: =N49-N50 -> 0
A52: Trésorerie finale | C52: =C48+C51 -> 0 | D52: =D48+D51 -> 0 | E52: =E48+E51 -> 0 | F52: =F48+F51 -> 0 | G52: =G48+G51 -> 0 | H52: =H48+H51 -> 0 | I52: =I48+I51 -> 0 | J52: =J48+J51 -> 0 | ... N52: =N48+N51 -> 0
A57: Elements Periodes | C57: Avril 1-7 | D57: Avril 8-15 | E57: Avril 16-23 | F57: Avril 24-30 | G57: Mai 1-7 | H57: Mai 8-15 | I57: Mai 16-23 | J57: Mai 24-31 | K57: Juin 1-7 | L57: Juin 8-15 | M57: Juin 16-23 | N57: Juin 24-30
A58: Encaissements
A59: Clients | B59: Henkel | C59: ='[1]Prévisions Entrées-Encaiss'!C42 -> 0 | D59: ='[1]Prévisions Entrées-Encaiss'!D42 -> 0 | E59: ='[1]Prévisions Entrées-Encaiss'!E42 -> 0 | F59: ='[1]Prévisions Entrées-Encaiss'!F42 -> 0 | G59: ='[1]Prévisions Entrées-Encaiss'!G42 -> 0 | H59: ='[1]Prévisions Entrées-Encaiss'!H42 -> 0 | I59: ='[1]Prévisions Entrées-Encaiss'!I42 -> 0 | J59: ='[1]Prévisions Entrées-Encaiss'!J42 -> 0 | ... N59: ='[1]Prévisions Entrées-Encaiss'!N42 -> 0
B60: KNAUF | C60: ='[1]Prévisions Entrées-Encaiss'!C43 -> 0 | D60: ='[1]Prévisions Entrées-Encaiss'!D43 -> 0 | E60: ='[1]Prévisions Entrées-Encaiss'!E43 -> 0 | F60: ='[1]Prévisions Entrées-Encaiss'!F43 -> 0 | G60: ='[1]Prévisions Entrées-Encaiss'!G43 -> 0 | H60: ='[1]Prévisions Entrées-Encaiss'!H43 -> 0 | I60: ='[1]Prévisions Entrées-Encaiss'!I43 -> 0 | J60: ='[1]Prévisions Entrées-Encaiss'!J43 -> 0 | ... N60: ='[1]Prévisions Entrées-Encaiss'!N43 -> 0
B61: MyTeamConnect | C61: ='[1]Prévisions Entrées-Encaiss'!C44 -> 0 | D61: ='[1]Prévisions Entrées-Encaiss'!D44 -> 0 | E61: ='[1]Prévisions Entrées-Encaiss'!E44 -> 0 | F61: ='[1]Prévisions Entrées-Encaiss'!F44 -> 0 | G61: ='[1]Prévisions Entrées-Encaiss'!G44 -> 0 | H61: ='[1]Prévisions Entrées-Encaiss'!H44 -> 0 | I61: ='[1]Prévisions Entrées-Encaiss'!I44 -> 0 | J61: ='[1]Prévisions Entrées-Encaiss'!J44 -> 0 | ... N61: ='[1]Prévisions Entrées-Encaiss'!N44 -> 0
B62: Lafarge | C62: ='[1]Prévisions Entrées-Encaiss'!C45 -> 0 | D62: ='[1]Prévisions Entrées-Encaiss'!D45 -> 0 | E62: ='[1]Prévisions Entrées-Encaiss'!E45 -> 0 | F62: ='[1]Prévisions Entrées-Encaiss'!F45 -> 0 | G62: ='[1]Prévisions Entrées-Encaiss'!G45 -> 0 | H62: ='[1]Prévisions Entrées-Encaiss'!H45 -> 0 | I62: ='[1]Prévisions Entrées-Encaiss'!I45 -> 0 | J62: ='[1]Prévisions Entrées-Encaiss'!J45 -> 0 | ... N62: ='[1]Prévisions Entrées-Encaiss'!N45 -> 0
B63: DIGITAL NATIVES | C63: ='[1]Prévisions Entrées-Encaiss'!C46 -> 0 | D63: ='[1]Prévisions Entrées-Encaiss'!D46 -> 0 | E63: ='[1]Prévisions Entrées-Encaiss'!E46 -> 0 | F63: ='[1]Prévisions Entrées-Encaiss'!F46 -> 0 | G63: ='[1]Prévisions Entrées-Encaiss'!G46 -> 0 | H63: ='[1]Prévisions Entrées-Encaiss'!H46 -> 0 | I63: ='[1]Prévisions Entrées-Encaiss'!I46 -> 0 | J63: ='[1]Prévisions Entrées-Encaiss'!J46 -> 0 | ... N63: ='[1]Prévisions Entrées-Encaiss'!N46 -> 0
B64: Beyond | C64: ='[1]Prévisions Entrées-Encaiss'!C47 -> 0 | D64: ='[1]Prévisions Entrées-Encaiss'!D47 -> 0 | E64: ='[1]Prévisions Entrées-Encaiss'!E47 -> 0 | F64: ='[1]Prévisions Entrées-Encaiss'!F47 -> 0 | G64: ='[1]Prévisions Entrées-Encaiss'!G47 -> 0 | H64: ='[1]Prévisions Entrées-Encaiss'!H47 -> 0 | I64: ='[1]Prévisions Entrées-Encaiss'!I47 -> 0 | J64: ='[1]Prévisions Entrées-Encaiss'!J47 -> 0 | ... N64: ='[1]Prévisions Entrées-Encaiss'!N47 -> 0
...
